Workbook

Sheet Estimates of the use of water (
A1: name | B1: year | C1: y_diff | D1: pop_n | E1: pop_u | F1: wat_bas_n | G1: ARC_n | H1: ARC_r | I1: ARC_u | J1: ARC_diff | K1: wat_lim_n | L1: wat_unimp_n | M1: wat_sur_n | N1: wat_bas_r | O1: wat_lim_r | P1: wat_unimp_r | Q1: wat_sur_r | R1: wat_bas_u | S1: wat_lim_u | T1: wat_unimp_u | U1: wat_sur_u
A2: Afghanistan | B2: 2015 | C2: =IF(A3=Estimates_of_the_use_of_water__2000_2020[[#This Row],[name]], B3-Estimates_of_the_use_of_water__2000_2020[[#This Row],[year]],"") -> 5 | D2: 34413.602 | E2: 24.802999 | F2: 61.339781 | G2: =((F3-Estimates_of_the_use_of_water__2000_2020[[#This Row],[wat_bas_n]])/(B3-Estimates_of_the_use_of_water__2000_2020[[#This Row],[year]])) -> 2.7503265 | H2: =((N3-Estimates_of_the_use_of_water__2000_2020[[#This Row],[wat_bas_r]])/(B3-Estimates_of_the_use_of_water__2000_2020[[#This Row],[year]])) -> 2.6678826 | I2: =(R3-Estimates_of_the_use_of_water__2000_2020[[#This Row],[wat_bas_u]])/(B3-Estimates_of_the_use_of_water__2000_2020[[#This Row],[year]]) -> 2.6682119 | J2: =ABS(Estimates_of_the_use_of_water__2000_2020[[#This Row],[ARC_r]]-Estimates_of_the_use_of_water__2000_2020[[#This Row],[ARC_u]]) -> 0.000329218 | K2: 3.5111995 | L2: 22.168784 | M2: 12.980236 | N2: 52.988502 | O2: 3.8611366 | P2: 26.553268 | Q2: 16.597094 | R2: 86.658941 | S2: 2.4502706 | T2: 8.8760357 | U2: 2.014753
A3: Afghanistan | B3: 2020 | C3: =IF(A4=Estimates_of_the_use_of_water__2000_2020[[#This Row],[name]], B4-Estimates_of_the_use_of_water__2000_2020[[#This Row],[year]],"") | D3: 38928.34 | E3: 26.025999 | F3: 75.091413 | G3: =((F4-Estimates_of_the_use_of_water__2000_2020[[#This Row],[wat_bas_n]])/(B4-Estimates_of_the_use_of_water__2000_2020[[#This Row],[year]])) -> -3.6605824 | H3: =((N4-Estimates_of_the_use_of_water__2000_2020[[#This Row],[wat_bas_r]])/(B4-Estimates_of_the_use_of_water__2000_2020[[#This Row],[year]])) -> -4.8598719 | I3: =(R4-Estimates_of_the_use_of_water__2000_2020[[#This Row],[wat_bas_u]])/(B4-Estimates_of_the_use_of_water__2000_2020[[#This Row],[year]]) -> 0.91098661 | J3: =ABS(Estimates_of_the_use_of_water__2000_2020[[#This Row],[ARC_r]]-Estimates_of_the_use_of_water__2000_2020[[#This Row],[ARC_u]]) -> 5.7708585 | K3: 1.4475417 | L3: 14.560263 | M3: 8.9007822 | N3: 66.327915 | O3: 1.9568249 | P3: 19.682949 | Q3: 12.032311 | R3: 100 | S3: 0 | T3: 0 | U3: 0
A4: Albania | B4: 2015 | C4: =IF(A5=Estimates_of_the_use_of_water__2000_2020[[#This Row],[name]], B5-Estimates_of_the_use_of_water__2000_2020[[#This Row],[year]],"") -> 5 | D4: 2890.5239 | E4: 57.433998 | F4: 93.394325 | G4: =((F5-Estimates_of_the_use_of_water__2000_2020[[#This Row],[wat_bas_n]])/(B5-Estimates_of_the_use_of_water__2000_2020[[#This Row],[year]])) -> 0.3347427 | H4: =((N5-Estimates_of_the_use_of_water__2000_2020[[#This Row],[wat_bas_r]])/(B5-Estimates_of_the_use_of_water__2000_2020[[#This Row],[year]])) -> 0.69281669 | I4: =(R5-Estimates_of_the_use_of_water__2000_2020[[#This Row],[wat_bas_u]])/(B5-Estimates_of_the_use_of_water__2000_2020[[#This Row],[year]]) -> 0.043748432 | J4: =ABS(Estimates_of_the_use_of_water__2000_2020[[#This Row],[ARC_r]]-Estimates_of_the_use_of_water__2000_2020[[#This Row],[ARC_u]]) -> 0.64906826 | K4: 3.6263837 | L4: 2.979291 | M4: 0 | N4: 90.627275 | O4: 5.2631726 | P4: 4.1095527 | Q4: 0 | R4: 95.445067 | S4: 2.4133118 | T4: 2.1416212 | U4: 0
A5: Albania | B5: 2020 | C5: =IF(A6=Estimates_of_the_use_of_water__2000_2020[[#This Row],[name]], B6-Estimates_of_the_use_of_water__2000_2020[[#This Row],[year]],"") | D5: 2877.8 | E5: 62.112 | F5: 95.068039 | G5: =((F6-Estimates_of_the_use_of_water__2000_2020[[#This Row],[wat_bas_n]])/(B6-Estimates_of_the_use_of_water__2000_2020[[#This Row],[year]])) -> 0.33169546 | H5: =((N6-Estimates_of_the_use_of_water__2000_2020[[#This Row],[wat_bas_r]])/(B6-Estimates_of_the_use_of_water__2000_2020[[#This Row],[year]])) -> 1.1477302 | I5: =(R6-Estimates_of_the_use_of_water__2000_2020[[#This Row],[wat_bas_u]])/(B6-Estimates_of_the_use_of_water__2000_2020[[#This Row],[year]]) -> 0.034698884 | J5: =ABS(Estimates_of_the_use_of_water__2000_2020[[#This Row],[ARC_r]]-Estimates_of_the_use_of_water__2000_2020[[#This Row],[ARC_u]]) -> 1.1130314 | K5: 1.8846561 | L5: 3.0473051 | M5: 0 | N5: 94.091358 | O5: 2.305265 | P5: 3.603377 | Q5: 0 | R5: 95.663809 | S5: 1.6280868 | T5: 2.7081041 | U5: 0
A6: Algeria | B6: 2015 | C6: =IF(A7=Estimates_of_the_use_of_water__2000_2020[[#This Row],[name]], B7-Estimates_of_the_use_of_water__2000_2020[[#This Row],[year]],"") -> 5 | D6: 39728.02 | E6: 70.848 | F6: 93.409562 | G6: =((F7-Estimates_of_the_use_of_water__2000_2020[[#This Row],[wat_bas_n]])/(B7-Estimates_of_the_use_of_water__2000_2020[[#This Row],[year]])) -> 0.20555369 | H6: =((N7-Estimates_of_the_use_of_water__2000_2020[[#This Row],[wat_bas_r]])/(B7-Estimates_of_the_use_of_water__2000_2020[[#This Row],[year]])) -> 0.33696621 | I6: =(R7-Estimates_of_the_use_of_water__2000_2020[[#This Row],[wat_bas_u]])/(B7-Estimates_of_the_use_of_water__2000_2020[[#This Row],[year]]) -> 0.10288423 | J6: =ABS(Estimates_of_the_use_of_water__2000_2020[[#This Row],[ARC_r]]-Estimates_of_the_use_of_water__2000_2020[[#This Row],[ARC_u]]) -> 0.23408198 | K6: 5.1577809 | L6: 1.2754647 | M6: 0.15719289 | N6: 88.352707 | O6: 8.6857531 | P6: 2.5804318 | Q6: 0.38110822 | R6: 95.490315 | S6: 3.7061173 | T6: 0.73851009 | U6: 0.065057898
A7: Algeria | B7: 2020 | C7: =IF(A8=Estimates_of_the_use_of_water__2000_2020[[#This Row],[name]], B8-Estimates_of_the_use_of_water__2000_2020[[#This Row],[year]],"") | D7: 43851.043 | E7: 73.733002 | F7: 94.43733 | G7: =((F8-Estimates_of_the_use_of_water__2000_2020[[#This Row],[wat_bas_n]])/(B8-Estimates_of_the_use_of_water__2000_2020[[#This Row],[year]])) -> -1.0363546 | H7: =((N8-Estimates_of_the_use_of_water__2000_2020[[#This Row],[wat_bas_r]])/(B8-Estimates_of_the_use_of_water__2000_2020[[#This Row],[year]])) -> 18.007508 | I7: =(R8-Estimates_of_the_use_of_water__2000_2020[[#This Row],[wat_bas_u]])/(B8-Estimates_of_the_use_of_water__2000_2020[[#This Row],[year]]) -> 19.200947 | J7: =ABS(Estimates_of_the_use_of_water__2000_2020[[#This Row],[ARC_r]]-Estimates_of_the_use_of_water__2000_2020[[#This Row],[ARC_u]]) -> 1.1934396 | K7: 4.9858808 | L7: 0.53183666 | M7: 0.044952533 | N7: 90.037538 | O7: 8.7967221 | P7: 0.99460303 | Q7: 0.17113693 | R7: 96.004736 | S7: 3.6282886 | T7: 0.36697555 | U7: 0
A8: American Samoa | B8: 2015 | C8: =IF(A9=Estimates_of_the_use_of_water__2000_2020[[#This Row],[name]], B9-Estimates_of_the_use_of_water__2000_2020[[#This Row],[year]],"") -> 5 | D8: 55.806 | E8: 87.238007 | F8: 99.619103 | G8: =((F9-Estimates_of_the_use_of_water__2000_2020[[#This Row],[wat_bas_n]])/(B9-Estimates_of_the_use_of_water__2000_2020[[#This Row],[year]])) -> 0.030933702 | H8: =((N9-Estimates_of_the_use_of_water__2000_2020[[#This Row],[wat_bas_r]])/(B9-Estimates_of_the_use_of_water__2000_2020[[#This Row],[year]])) -> 0 | I8: =(R9-Estimates_of_the_use_of_water__2000_2020[[#This Row],[wat_bas_u]])/(B9-Estimates_of_the_use_of_water__2000_2020[[#This Row],[year]]) -> 0 | J8: =ABS(Estimates_of_the_use_of_water__2000_2020[[#This Row],[ARC_r]]-Estimates_of_the_use_of_water__2000_2020[[#This Row],[ARC_u]]) -> 0 | K8: 0 | L8: 0.38089685 | M8: 0
A9: American Samoa | B9: 2020 | C9: =IF(A10=Estimates_of_the_use_of_water__2000_2020[[#This Row],[name]], B10-Estimates_of_the_use_of_water__2000_2020[[#This Row],[year]],"") | D9: 55.196999 | E9: 87.153 | F9: 99.773772 | G9: =((F10-Estimates_of_the_use_of_water__2000_2020[[#This Row],[wat_bas_n]])/(B10-Estimates_of_the_use_of_water__2000_2020[[#This Row],[year]])) -> -0.045245178 | H9: =((N10-Estimates_of_the_use_of_water__2000_2020[[#This Row],[wat_bas_r]])/(B10-Estimates_of_the_use_of_water__2000_2020[[#This Row],[year]])) -> -20 | I9: =(R10-Estimates_of_the_use_of_water__2000_2020[[#This Row],[wat_bas_u]])/(B10-Estimates_of_the_use_of_water__2000_2020[[#This Row],[year]]) -> -20 | J9: =ABS(Estimates_of_the_use_of_water__2000_2020[[#This Row],[ARC_r]]-Estimates_of_the_use_of_water__2000_2020[[#This Row],[ARC_u]]) -> 0 | K9: 0 | L9: 0.22622834 | M9: 0
A10: Andorra | B10: 2015 | C10: =IF(A11=Estimates_of_the_use_of_water__2000_2020[[#This Row],[name]], B11-Estimates_of_the_use_of_water__2000_2020[[#This Row],[year]],"") -> 5 | D10: 77.992996 | E10: 88.344994 | F10: 99.999998 | G10: =((F11-Estimates_of_the_use_of_water__2000_2020[[#This Row],[wat_bas_n]])/(B11-Estimates_of_the_use_of_water__2000_2020[[#This Row],[year]])) -> 1.23e-06 | H10: =((N11-Estimates_of_the_use_of_water__2000_2020[[#This Row],[wat_bas_r]])/(B11-Estimates_of_the_use_of_water__2000_2020[[#This Row],[year]])) -> 0 | I10: =(R11-Estimates_of_the_use_of_water__2000_2020[[#This Row],[wat_bas_u]])/(B11-Estimates_of_the_use_of_water__2000_2020[[#This Row],[year]]) -> 0 | J10: =ABS(Estimates_of_the_use_of_water__2000_2020[[#This Row],[ARC_r]]-Estimates_of_the_use_of_water__2000_2020[[#This Row],[ARC_u]]) -> 0 | K10: 0 | L10: 2.4455384e-06 | M10: 0 | N10: 100 | O10: 0 | P10: 0 | Q10: 0 | R10: 100 | S10: 0 | T10: 0 | U10: 0
A11: Andorra | B11: 2020 | C11: =IF(A12=Estimates_of_the_use_of_water__2000_2020[[#This Row],[name]], B12-Estimates_of_the_use_of_water__2000_2020[[#This Row],[year]],"") | D11: 77.264999 | E11: 87.916 | F11: 100 | G11: =((F12-Estimates_of_the_use_of_water__2000_2020[[#This Row],[wat_bas_n]])/(B12-Estimates_of_the_use_of_water__2000_2020[[#This Row],[year]])) -> 9.1366151 | H11: =((N12-Estimates_of_the_use_of_water__2000_2020[[#This Row],[wat_bas_r]])/(B12-Estimates_of_the_use_of_water__2000_2020[[#This Row],[year]])) -> 14.657126 | I11: =(R12-Estimates_of_the_use_of_water__2000_2020[[#This Row],[wat_bas_u]])/(B12-Estimates_of_the_use_of_water__2000_2020[[#This Row],[year]]) -> 5.956007 | J11: =ABS(Estimates_of_the_use_of_water__2000_2020[[#This Row],[ARC_r]]-Estimates_of_the_use_of_water__2000_2020[[#This Row],[ARC_u]]) -> 8.7011191 | K11: 0 | L11: 0 | M11: 0 | N11: 100 | O11: 0 | P11: 0 | Q11: 0 | R11: 100 | S11: 0 | T11: 0 | U11: 0
A12: Angola | B12: 2015 | C12: =IF(A13=Estimates_of_the_use_of_water__2000_2020[[#This Row],[name]], B13-Estimates_of_the_use_of_water__2000_2020[[#This Row],[year]],"") -> 5 | D12: 27884.381 | E12: 63.445995 | F12: 54.316928 | G12: =((F13-Estimates_of_the_use_of_water__2000_2020[[#This Row],[wat_bas_n]])/(B13-Estimates_of_the_use_of_water__2000_2020[[#This Row],[year]])) -> 0.57016185 | H12: =((N13-Estimates_of_the_use_of_water__2000_2020[[#This Row],[wat_bas_r]])/(B13-Estimates_of_the_use_of_water__2000_2020[[#This Row],[year]])) -> 0.21877144 | I12: =(R13-Estimates_of_the_use_of_water__2000_2020[[#This Row],[wat_bas_u]])/(B13-Estimates_of_the_use_of_water__2000_2020[[#This Row],[year]]) -> 0.3046367 | J12: =ABS(Estimates_of_the_use_of_water__2000_2020[[#This Row],[ARC_r]]-Estimates_of_the_use_of_water__2000_2020[[#This Row],[ARC_u]]) -> 0.085865258 | K12: 11.368619 | L12: 17.372356 | M12: 16.942097 | N12: 26.714369 | O12: 9.9310693 | P12: 21.725308 | Q12: 41.629254 | R12: 70.219965 | S12: 12.196853 | T12: 14.864431 | U12: 2.7187499
A13: Angola | B13: 2020 | C13: =IF(A14=Estimates_of_the_use_of_water__2000_2020[[#This Row],[name]], B14-Estimates_of_the_use_of_water__2000_2020[[#This Row],[year]],"") | D13: 32866.27 | E13: 66.824997 | F13: 57.167738 | G13: =((F14-Estimates_of_the_use_of_water__2000_2020[[#This Row],[wat_bas_n]])/(B14-Estimates_of_the_use_of_water__2000_2020[[#This Row],[year]])) -> -8.0629073 | H13: =((N14-Estimates_of_the_use_of_water__2000_2020[[#This Row],[wat_bas_r]])/(B14-Estimates_of_the_use_of_water__2000_2020[[#This Row],[year]])) -> 5.5616453 | I13: =(R14-Estimates_of_the_use_of_water__2000_2020[[#This Row],[wat_bas_u]])/(B14-Estimates_of_the_use_of_water__2000_2020[[#This Row],[year]]) -> -5.1478251 | J13: =ABS(Estimates_of_the_use_of_water__2000_2020[[#This Row],[ARC_r]]-Estimates_of_the_use_of_water__2000_2020[[#This Row],[ARC_u]]) -> 10.70947 | K13: 9.2873499 | L13: 19.450825 | M13: 14.094087 | N13: 27.808227 | O13: 8.7404884 | P13: 22.933153 | Q13: 40.518132 | R13: 71.743149 | S13: 9.5588375 | T13: 17.722035 | U13: 0.97597916
A14: Anguilla | B14: 2015 | C14: =IF(A15=Estimates_of_the_use_of_water__2000_2020[[#This Row],[name]], B15-Estimates_of_the_use_of_water__2000_2020[[#This Row],[year]],"") -> 2 | D14: 14.279 | E14: 100 | F14: 97.482274 | G14: =((F15-Estimates_of_the_use_of_water__2000_2020[[#This Row],[wat_bas_n]])/(B15-Estimates_of_the_use_of_water__2000_2020[[#This Row],[year]])) -> 0 | H14: =((N15-Estimates_of_the_use_of_water__2000_2020[[#This Row],[wat_bas_r]])/(B15-Estimates_of_the_use_of_water__2000_2020[[#This Row],[year]])) -> 0 | I14: =(R15-Estimates_of_the_use_of_water__2000_2020[[#This Row],[wat_bas_u]])/(B15-Estimates_of_the_use_of_water__2000_2020[[#This Row],[year]]) -> 0 | J14: =ABS(Estimates_of_the_use_of_water__2000_2020[[#This Row],[ARC_r]]-Estimates_of_the_use_of_water__2000_2020[[#This Row],[ARC_u]]) -> 0 | K14: 0 | L14: 2.5177258 | M14: 0 | R14: 97.482274 | S14: 0 | T14: 2.5177258 | U14: 0
A15: Anguilla | B15: 2017 | C15: =IF(A16=Estimates_of_the_use_of_water__2000_2020[[#This Row],[name]], B16-Estimates_of_the_use_of_water__2000_2020[[#This Row],[year]],"") | D15: 14.588 | E15: 100 | F15: 97.482274 | G15: =((F16-Estimates_of_the_use_of_water__2000_2020[[#This Row],[wat_bas_n]])/(B16-Estimates_of_the_use_of_water__2000_2020[[#This Row],[year]])) -> 0.37154399 | H15: =((N16-Estimates_of_the_use_of_water__2000_2020[[#This Row],[wat_bas_r]])/(B16-Estimates_of_the_use_of_water__2000_2020[[#This Row],[year]])) -> 0 | I15: =(R16-Estimates_of_the_use_of_water__2000_2020[[#This Row],[wat_bas_u]])/(B16-Estimates_of_the_use_of_water__2000_2020[[#This Row],[year]]) -> 48.741137 | J15: =ABS(Estimates_of_the_use_of_water__2000_2020[[#This Row],[ARC_r]]-Estimates_of_the_use_of_water__2000_2020[[#This Row],[ARC_u]]) -> 48.741137 | K15: 0 | L15: 2.5177258 | M15: 0 | R15: 97.482274 | S15: 0 | T15: 2.5177258 | U15: 0
A16: Antigua and Barbuda | B16: 2015 | C16: =IF(A17=Estimates_of_the_use_of_water__2000_2020[[#This Row],[name]], B17-Estimates_of_the_use_of_water__2000_2020[[#This Row],[year]],"") -> 2 | D16: 93.570999 | E16: 25 | F16: 96.739186 | G16: =((F17-Estimates_of_the_use_of_water__2000_2020[[#This Row],[wat_bas_n]])/(B17-Estimates_of_the_use_of_water__2000_2020[[#This Row],[year]])) -> 0 | H16: =((N17-Estimates_of_the_use_of_water__2000_2020[[#This Row],[wat_bas_r]])/(B17-Estimates_of_the_use_of_water__2000_2020[[#This Row],[year]])) -> 0 | I16: =(R17-Estimates_of_the_use_of_water__2000_2020[[#This Row],[wat_bas_u]])/(B17-Estimates_of_the_use_of_water__2000_2020[[#This Row],[year]]) -> 0 | J16: =ABS(Estimates_of_the_use_of_water__2000_2020[[#This Row],[ARC_r]]-Estimates_of_the_use_of_water__2000_2020[[#This Row],[ARC_u]]) -> 0 | K16: 0 | L16: 3.1663476 | M16: 0.094466114
A17: Antigua and Barbuda | B17: 2017 | C17: =IF(A18=Estimates_of_the_use_of_water__2000_2020[[#This Row],[name]], B18-Estimates_of_the_use_of_water__2000_2020[[#This Row],[year]],"") | D17: 95.425003 | E17: 24.713001 | F17: 96.739186 | G17: =((F18-Estimates_of_the_use_of_water__2000_2020[[#This Row],[wat_bas_n]])/(B18-Estimates_of_the_use_of_water__2000_2020[[#This Row],[year]])) -> -1.1137009 | H17: =((N18-Estimates_of_the_use_of_water__2000_2020[[#This Row],[wat_bas_r]])/(B18-Estimates_of_the_use_of_water__2000_2020[[#This Row],[year]])) -> -46.49183 | I17: =(R18-Estimates_of_the_use_of_water__2000_2020[[#This Row],[wat_bas_u]])/(B18-Estimates_of_the_use_of_water__2000_2020[[#This Row],[year]]) -> -49.761082 | J17: =ABS(Estimates_of_the_use_of_water__2000_2020[[#This Row],[ARC_r]]-Estimates_of_the_use_of_water__2000_2020[[#This Row],[ARC_u]]) -> 3.2692515 | K17: 0 | L17: 3.1663476 | M17: 0.094466114
A18: Argentina | B18: 2015 | C18: =IF(A19=Estimates_of_the_use_of_water__2000_2020[[#This Row],[name]], B19-Estimates_of_the_use_of_water__2000_2020[[#This Row],[year]],"") -> 5 | D18: 43075.414 | E18: 91.502998 | F18: 98.966588 | G18: =((F19-Estimates_of_the_use_of_water__2000_2020[[#This Row],[wat_bas_n]])/(B19-Estimates_of_the_use_of_water__2000_2020[[#This Row],[year]])) -> -19.793318 | H18: =((N19-Estimates_of_the_use_of_water__2000_2020[[#This Row],[wat_bas_r]])/(B19-Estimates_of_the_use_of_water__2000_2020[[#This Row],[year]])) -> -18.596732 | I18: =(R19-Estimates_of_the_use_of_water__2000_2020[[#This Row],[wat_bas_u]])/(B19-Estimates_of_the_use_of_water__2000_2020[[#This Row],[year]]) -> 0.05365152 | J18: =ABS(Estimates_of_the_use_of_water__2000_2020[[#This Row],[ARC_r]]-Estimates_of_the_use_of_water__2000_2020[[#This Row],[ARC_u]]) -> 18.650384 | K18: 0 | L18: 0.66491438 | M18: 0.36849747 | N18: 92.98366 | O18: 0 | P18: 2.6795449 | Q18: 4.3367951 | R18: 99.522163 | S18: 0 | T18: 0.47783695 | U18: 0
A19: Argentina | B19: 2020 | C19: =IF(A20=Estimates_of_the_use_of_water__2000_2020[[#This Row],[name]], B20-Estimates_of_the_use_of_water__2000_2020[[#This Row],[year]],"") | D19: 45195.777 | E19: 92.111 | G19: =((F20-Estimates_of_the_use_of_water__2000_2020[[#This Row],[wat_bas_n]])/(B20-Estimates_of_the_use_of_water__2000_2020[[#This Row],[year]])) -> -19.910513 | H19: =((N20-Estimates_of_the_use_of_water__2000_2020[[#This Row],[wat_bas_r]])/(B20-Estimates_of_the_use_of_water__2000_2020[[#This Row],[year]])) -> -19.810956 | I19: =(R20-Estimates_of_the_use_of_water__2000_2020[[#This Row],[wat_bas_u]])/(B20-Estimates_of_the_use_of_water__2000_2020[[#This Row],[year]]) -> -0.01068655 | J19: =ABS(Estimates_of_the_use_of_water__2000_2020[[#This Row],[ARC_r]]-Estimates_of_the_use_of_water__2000_2020[[#This Row],[ARC_u]]) -> 19.800269 | R19: 99.790421 | S19: 0 | T19: 0.20957935 | U19: 0
A20: Armenia | B20: 2015 | C20: =IF(A21=Estimates_of_the_use_of_water__2000_2020[[#This Row],[name]], B21-Estimates_of_the_use_of_water__2000_2020[[#This Row],[year]],"") -> 5 | D20: 2925.5591 | E20: 63.085003 | F20: 99.552567 | G20: =((F21-Estimates_of_the_use_of_water__2000_2020[[#This Row],[wat_bas_n]])/(B21-Estimates_of_the_use_of_water__2000_2020[[#This Row],[year]])) -> 0.083722798 | H20: =((N21-Estimates_of_the_use_of_water__2000_2020[[#This Row],[wat_bas_r]])/(B21-Estimates_of_the_use_of_water__2000_2020[[#This Row],[year]])) -> 0.18904415 | I20: =(R21-Estimates_of_the_use_of_water__2000_2020[[#This Row],[wat_bas_u]])/(B21-Estimates_of_the_use_of_water__2000_2020[[#This Row],[year]]) -> 0.022125564 | J20: =ABS(Estimates_of_the_use_of_water__2000_2020[[#This Row],[ARC_r]]-Estimates_of_the_use_of_water__2000_2020[[#This Row],[ARC_u]]) -> 0.16691858 | K20: 0 | L20: 0.098505084 | M20: 0.34892822 | N20: 99.054779 | O20: 0 | P20: 0 | Q20: 0.94522073 | R20: 99.843853 | S20: 0 | T20: 0.1561466 | U20: 0
A21: Armenia | B21: 2020 | C21: =IF(A22=Estimates_of_the_use_of_water__2000_2020[[#This Row],[name]], B22-Estimates_of_the_use_of_water__2000_2020[[#This Row],[year]],"") | D21: 2963.2339 | E21: 63.313 | F21: 99.971181 | G21: =((F22-Estimates_of_the_use_of_water__2000_2020[[#This Row],[wat_bas_n]])/(B22-Estimates_of_the_use_of_water__2000_2020[[#This Row],[year]])) -> 0.42043146 | H21: =((N22-Estimates_of_the_use_of_water__2000_2020[[#This Row],[wat_bas_r]])/(B22-Estimates_of_the_use_of_water__2000_2020[[#This Row],[year]])) -> 20 | I21: =(R22-Estimates_of_the_use_of_water__2000_2020[[#This Row],[wat_bas_u]])/(B22-Estimates_of_the_use_of_water__2000_2020[[#This Row],[year]]) -> 19.990896 | J21: =ABS(Estimates_of_the_use_of_water__2000_2020[[#This Row],[ARC_r]]-Estimates_of_the_use_of_water__2000_2020[[#This Row],[ARC_u]]) -> 0.009103756 | K21: 0 | L21: 0.028819308 | M21: 0 | N21: 100 | O21: 0 | P21: 0 | Q21: 0 | R21: 99.954481 | S21: 0 | T21: 0.045518784 | U21: 0
A22: Aruba | B22: 2015 | C22: =IF(A23=Estimates_of_the_use_of_water__2000_2020[[#This Row],[name]], B23-Estimates_of_the_use_of_water__2000_2020[[#This Row],[year]],"") -> 1 | D22: 104.339 | E22: 43.108002 | F22: 97.869023 | G22: =((F23-Estimates_of_the_use_of_water__2000_2020[[#This Row],[wat_bas_n]])/(B23-Estimates_of_the_use_of_water__2000_2020[[#This Row],[year]])) -> 0 | H22: =((N23-Estimates_of_the_use_of_water__2000_2020[[#This Row],[wat_bas_r]])/(B23-Estimates_of_the_use_of_water__2000_2020[[#This Row],[year]])) -> 0 | I22: =(R23-Estimates_of_the_use_of_water__2000_2020[[#This Row],[wat_bas_u]])/(B23-Estimates_of_the_use_of_water__2000_2020[[#This Row],[year]]) -> 0 | J22: =ABS(Estimates_of_the_use_of_water__2000_2020[[#This Row],[ARC_r]]-Estimates_of_the_use_of_water__2000_2020[[#This Row],[ARC_u]]) -> 0 | K22: 0 | L22: 1.9599362 | M22: 0.17104041
A23: Aruba | B23: 2016 | C23: =IF(A24=Estimates_of_the_use_of_water__2000_2020[[#This Row],[name]], B24-Estimates_of_the_use_of_water__2000_2020[[#This Row],[year]],"") | D23: 104.865 | E23: 43.191998 | F23: 97.869023 | G23: =((F24-Estimates_of_the_use_of_water__2000_2020[[#This Row],[wat_bas_n]])/(B24-Estimates_of_the_use_of_water__2000_2020[[#This Row],[year]])) -> -2.1009823 | H23: =((N24-Estimates_of_the_use_of_water__2000_2020[[#This Row],[wat_bas_r]])/(B24-Estimates_of_the_use_of_water__2000_2020[[#This Row],[year]])) -> -100 | I23: =(R24-Estimates_of_the_use_of_water__2000_2020[[#This Row],[wat_bas_u]])/(B24-Estimates_of_the_use_of_water__2000_2020[[#This Row],[year]]) -> -99.965 | J23: =ABS(Estimates_of_the_use_of_water__2000_2020[[#This Row],[ARC_r]]-Estimates_of_the_use_of_water__2000_2020[[#This Row],[ARC_u]]) -> 0.035 | K23: 0 | L23: 1.9599362 | M23: 0.17104041
A24: Australia | B24: 2015 | C24: =IF(A25=Estimates_of_the_use_of_water__2000_2020[[#This Row],[name]], B25-Estimates_of_the_use_of_water__2000_2020[[#This Row],[year]],"") -> 5 | D24: 23932.498 | E24: 85.701004 | F24: 99.970006 | G24: =((F25-Estimates_of_the_use_of_water__2000_2020[[#This Row],[wat_bas_n]])/(B25-Estimates_of_the_use_of_water__2000_2020[[#This Row],[year]])) -> -3.877e-05 | H24: =((N25-Estimates_of_the_use_of_water__2000_2020[[#This Row],[wat_bas_r]])/(B25-Estimates_of_the_use_of_water__2000_2020[[#This Row],[year]])) -> 0 | I24: =(R25-Estimates_of_the_use_of_water__2000_2020[[#This Row],[wat_bas_u]])/(B25-Estimates_of_the_use_of_water__2000_2020[[#This Row],[year]]) -> 0 | J24: =ABS(Estimates_of_the_use_of_water__2000_2020[[#This Row],[ARC_r]]-Estimates_of_the_use_of_water__2000_2020[[#This Row],[ARC_u]]) -> 0 | K24: 0 | L24: 0.029994331 | M24: 0 | N24: 100 | O24: 0 | P24: 0 | Q24: 0 | R24: 99.965 | S24: 0 | T24: 0.035 | U24: 0
A25: Australia | B25: 2020 | C25: =IF(A26=Estimates_of_the_use_of_water__2000_2020[[#This Row],[name]], B26-Estimates_of_the_use_of_water__2000_2020[[#This Row],[year]],"") | D25: 25499.881 | E25: 86.240997 | F25: 99.969812 | G25: =((F26-Estimates_of_the_use_of_water__2000_2020[[#This Row],[wat_bas_n]])/(B26-Estimates_of_the_use_of_water__2000_2020[[#This Row],[year]])) -> -0.006037636 | H25: =((N26-Estimates_of_the_use_of_water__2000_2020[[#This Row],[wat_bas_r]])/(B26-Estimates_of_the_use_of_water__2000_2020[[#This Row],[year]])) -> 0 | I25: =(R26-Estimates_of_the_use_of_water__2000_2020[[#This Row],[wat_bas_u]])/(B26-Estimates_of_the_use_of_water__2000_2020[[#This Row],[year]]) -> -0.007 | J25: =ABS(Estimates_of_the_use_of_water__2000_2020[[#This Row],[ARC_r]]-Estimates_of_the_use_of_water__2000_2020[[#This Row],[ARC_u]]) -> 0.007 | K25: 0 | L25: 0.030188179 | M25: 0 | N25: 100 | O25: 0 | P25: 0 | Q25: 0 | R25: 99.965 | S25: 0 | T25: 0.035 | U25: 0
A26: Austria | B26: 2015 | C26: =IF(A27=Estimates_of_the_use_of_water__2000_2020[[#This Row],[name]], B27-Estimates_of_the_use_of_water__2000_2020[[#This Row],[year]],"") -> 5 | D26: 8678.667 | E26: 57.715 | F26: 100 | G26: =((F27-Estimates_of_the_use_of_water__2000_2020[[#This Row],[wat_bas_n]])/(B27-Estimates_of_the_use_of_water__2000_2020[[#This Row],[year]])) -> 0 | H26: =((N27-Estimates_of_the_use_of_water__2000_2020[[#This Row],[wat_bas_r]])/(B27-Estimates_of_the_use_of_water__2000_2020[[#This Row],[year]])) -> 0 | I26: =(R27-Estimates_of_the_use_of_water__2000_2020[[#This Row],[wat_bas_u]])/(B27-Estimates_of_the_use_of_water__2000_2020[[#This Row],[year]]) -> 0 | J26: =ABS(Estimates_of_the_use_of_water__2000_2020[[#This Row],[ARC_r]]-Estimates_of_the_use_of_water__2000_2020[[#This Row],[ARC_u]]) -> 0 | K26: 0 | L26: 0 | M26: 0 | N26: 100 | O26: 0 | P26: 0 | Q26: 0 | R26: 100 | S26: 0 | T26: 0 | U26: 0
A27: Austria | B27: 2020 | C27: =IF(A28=Estimates_of_the_use_of_water__2000_2020[[#This Row],[name]], B28-Estimates_of_the_use_of_water__2000_2020[[#This Row],[year]],"") | D27: 9006.4004 | E27: 58.748001 | F27: 100 | G27: =((F28-Estimates_of_the_use_of_water__2000_2020[[#This Row],[wat_bas_n]])/(B28-Estimates_of_the_use_of_water__2000_2020[[#This Row],[year]])) -> 1.5159372 | H27: =((N28-Estimates_of_the_use_of_water__2000_2020[[#This Row],[wat_bas_r]])/(B28-Estimates_of_the_use_of_water__2000_2020[[#This Row],[year]])) -> 3.1713573 | I27: =(R28-Estimates_of_the_use_of_water__2000_2020[[#This Row],[wat_bas_u]])/(B28-Estimates_of_the_use_of_water__2000_2020[[#This Row],[year]]) -> 0.14576959 | J27: =ABS(Estimates_of_the_use_of_water__2000_2020[[#This Row],[ARC_r]]-Estimates_of_the_use_of_water__2000_2020[[#This Row],[ARC_u]]) -> 3.0255878 | K27: 0 | L27: 0 | M27: 0 | N27: 100 | O27: 0 | P27: 0 | Q27: 0 | R27: 100 | S27: 0 | T27: 0 | U27: 0
A28: Azerbaijan | B28: 2015 | C28: =IF(A29=Estimates_of_the_use_of_water__2000_2020[[#This Row],[name]], B29-Estimates_of_the_use_of_water__2000_2020[[#This Row],[year]],"") -> 5 | D28: 9622.7412 | E28: 54.714001 | F28: 92.420314 | G28: =((F29-Estimates_of_the_use_of_water__2000_2020[[#This Row],[wat_bas_n]])/(B29-Estimates_of_the_use_of_water__2000_2020[[#This Row],[year]])) -> 0.72461243 | H28: =((N29-Estimates_of_the_use_of_water__2000_2020[[#This Row],[wat_bas_r]])/(B29-Estimates_of_the_use_of_water__2000_2020[[#This Row],[year]])) -> 1.3565169 | I28: =(R29-Estimates_of_the_use_of_water__2000_2020[[#This Row],[wat_bas_u]])/(B29-Estimates_of_the_use_of_water__2000_2020[[#This Row],[year]]) -> 0.14576959 | J28: =ABS(Estimates_of_the_use_of_water__2000_2020[[#This Row],[ARC_r]]-Estimates_of_the_use_of_water__2000_2020[[#This Row],[ARC_u]]) -> 1.2107473 | K28: 1.0022424 | L28: 4.3650895 | M28: 2.2123541 | N28: 84.143213 | O28: 2.2131397 | P28: 8.988206 | Q28: 4.655441 | R28: 99.271152 | S28: 0 | T28: 0.53860203 | U28: 0.19024593
A29: Azerbaijan | B29: 2020 | C29: =IF(A30=Estimates_of_the_use_of_water__2000_2020[[#This Row],[name]], B30-Estimates_of_the_use_of_water__2000_2020[[#This Row],[year]],"") | D29: 10139.175 | E29: 56.397003 | F29: 96.043376 | G29: =((F30-Estimates_of_the_use_of_water__2000_2020[[#This Row],[wat_bas_n]])/(B30-Estimates_of_the_use_of_water__2000_2020[[#This Row],[year]])) -> -0.56871687 | H29: =((N30-Estimates_of_the_use_of_water__2000_2020[[#This Row],[wat_bas_r]])/(B30-Estimates_of_the_use_of_water__2000_2020[[#This Row],[year]])) -> 18.18516 | I29: =(R30-Estimates_of_the_use_of_water__2000_2020[[#This Row],[wat_bas_u]])/(B30-Estimates_of_the_use_of_water__2000_2020[[#This Row],[year]]) -> 20 | J29: =ABS(Estimates_of_the_use_of_water__2000_2020[[#This Row],[ARC_r]]-Estimates_of_the_use_of_water__2000_2020[[#This Row],[ARC_u]]) -> 1.8148404 | K29: 1.0427812 | L29: 2.9138427 | M29: 0 | N29: 90.925798 | O29: 2.3915357 | P29: 6.6826664 | Q29: 0 | R29: 100 | S29: 0 | T29: 0 | U29: 0
A30: Bahamas | B30: 2015 | C30: =IF(A31=Estimates_of_the_use_of_water__2000_2020[[#This Row],[name]], B31-Estimates_of_the_use_of_water__2000_2020[[#This Row],[year]],"") -> 4 | D30: 374.20001 | E30: 82.745995 | F30: 98.886961 | G30: =((F31-Estimates_of_the_use_of_water__2000_2020[[#This Row],[wat_bas_n]])/(B31-Estimates_of_the_use_of_water__2000_2020[[#This Row],[year]])) -> 0 | H30: =((N31-Estimates_of_the_use_of_water__2000_2020[[#This Row],[wat_bas_r]])/(B31-Estimates_of_the_use_of_water__2000_2020[[#This Row],[year]])) -> 0 | I30: =(R31-Estimates_of_the_use_of_water__2000_2020[[#This Row],[wat_bas_u]])/(B31-Estimates_of_the_use_of_water__2000_2020[[#This Row],[year]]) -> 0 | J30: =ABS(Estimates_of_the_use_of_water__2000_2020[[#This Row],[ARC_r]]-Estimates_of_the_use_of_water__2000_2020[[#This Row],[ARC_u]]) -> 0 | K30: 0 | L30: 1.1130395 | M30: 0
A31: Bahamas | B31: 2019 | C31: =IF(A32=Estimates_of_the_use_of_water__2000_2020[[#This Row],[name]], B32-Estimates_of_the_use_of_water__2000_2020[[#This Row],[year]],"") | D31: 389.48599 | E31: 83.131996 | F31: 98.886961 | G31: =((F32-Estimates_of_the_use_of_water__2000_2020[[#This Row],[wat_bas_n]])/(B32-Estimates_of_the_use_of_water__2000_2020[[#This Row],[year]])) -> -0.27825987 | H31: =((N32-Estimates_of_the_use_of_water__2000_2020[[#This Row],[wat_bas_r]])/(B32-Estimates_of_the_use_of_water__2000_2020[[#This Row],[year]])) -> 0 | I31: =(R32-Estimates_of_the_use_of_water__2000_2020[[#This Row],[wat_bas_u]])/(B32-Estimates_of_the_use_of_water__2000_2020[[#This Row],[year]]) -> 0 | J31: =ABS(Estimates_of_the_use_of_water__2000_2020[[#This Row],[ARC_r]]-Estimates_of_the_use_of_water__2000_2020[[#This Row],[ARC_u]]) -> 0 | K31: 0 | L31: 1.1130395 | M31: 0
A32: Bahrain | B32: 2015 | C32: =IF(A33=Estimates_of_the_use_of_water__2000_2020[[#This Row],[name]], B33-Estimates_of_the_use_of_water__2000_2020[[#This Row],[year]],"") -> 5 | D32: 1371.853 | E32: 88.998993 | F32: 100 | G32: =((F33-Estimates_of_the_use_of_water__2000_2020[[#This Row],[wat_bas_n]])/(B33-Estimates_of_the_use_of_water__2000_2020[[#This Row],[year]])) -> 0 | H32: =((N33-Estimates_of_the_use_of_water__2000_2020[[#This Row],[wat_bas_r]])/(B33-Estimates_of_the_use_of_water__2000_2020[[#This Row],[year]])) -> 0 | I32: =(R33-Estimates_of_the_use_of_water__2000_2020[[#This Row],[wat_bas_u]])/(B33-Estimates_of_the_use_of_water__2000_2020[[#This Row],[year]]) -> 0 | J32: =ABS(Estimates_of_the_use_of_water__2000_2020[[#This Row],[ARC_r]]-Estimates_of_the_use_of_water__2000_2020[[#This Row],[ARC_u]]) -> 0 | K32: 0 | L32: 0 | M32: 0
A33: Bahrain | B33: 2020 | C33: =IF(A34=Estimates_of_the_use_of_water__2000_2020[[#This Row],[name]], B34-Estimates_of_the_use_of_water__2000_2020[[#This Row],[year]],"") | D33: 1701.583 | E33: 89.506004 | F33: 100 | G33: =((F34-Estimates_of_the_use_of_water__2000_2020[[#This Row],[wat_bas_n]])/(B34-Estimates_of_the_use_of_water__2000_2020[[#This Row],[year]])) -> 0.57967951 | H33: =((N34-Estimates_of_the_use_of_water__2000_2020[[#This Row],[wat_bas_r]])/(B34-Estimates_of_the_use_of_water__2000_2020[[#This Row],[year]])) -> -19.354602 | I33: =(R34-Estimates_of_the_use_of_water__2000_2020[[#This Row],[wat_bas_u]])/(B34-Estimates_of_the_use_of_water__2000_2020[[#This Row],[year]]) -> -19.546156 | J33: =ABS(Estimates_of_the_use_of_water__2000_2020[[#This Row],[ARC_r]]-Estimates_of_the_use_of_water__2000_2020[[#This Row],[ARC_u]]) -> 0.19155368 | K33: 0 | L33: 0 | M33: 0
A34: Bangladesh | B34: 2015 | C34: =IF(A35=Estimates_of_the_use_of_water__2000_2020[[#This Row],[name]], B35-Estimates_of_the_use_of_water__2000_2020[[#This Row],[year]],"") -> 5 | D34: 156256.28 | E34: 34.308002 | F34: 97.101602 | G34: =((F35-Estimates_of_the_use_of_water__2000_2020[[#This Row],[wat_bas_n]])/(B35-Estimates_of_the_use_of_water__2000_2020[[#This Row],[year]])) -> 0.11927156 | H34: =((N35-Estimates_of_the_use_of_water__2000_2020[[#This Row],[wat_bas_r]])/(B35-Estimates_of_the_use_of_water__2000_2020[[#This Row],[year]])) -> 0.2214453 | I34: =(R35-Estimates_of_the_use_of_water__2000_2020[[#This Row],[wat_bas_u]])/(B35-Estimates_of_the_use_of_water__2000_2020[[#This Row],[year]]) -> -0.065600342 | J34: =ABS(Estimates_of_the_use_of_water__2000_2020[[#This Row],[ARC_r]]-Estimates_of_the_use_of_water__2000_2020[[#This Row],[ARC_u]]) -> 0.28704564 | K34: 1.087989 | L34: 0.72156166 | M34: 1.0888469 | N34: 96.773011 | O34: 1.0462142 | P34: 0.73174732 | Q34: 1.4490272 | R34: 97.73078 | S34: 1.1679782 | T34: 0.70205843 | U34: 0.39918371
A35: Bangladesh | B35: 2020 | C35: =IF(A36=Estimates_of_the_use_of_water__2000_2020[[#This Row],[name]], B36-Estimates_of_the_use_of_water__2000_2020[[#This Row],[year]],"") | D35: 164689.39 | E35: 38.177002 | F35: 97.69796 | G35: =((F36-Estimates_of_the_use_of_water__2000_2020[[#This Row],[wat_bas_n]])/(B36-Estimates_of_the_use_of_water__2000_2020[[#This Row],[year]])) -> -0.1552969 | H35: =((N36-Estimates_of_the_use_of_water__2000_2020[[#This Row],[wat_bas_r]])/(B36-Estimates_of_the_use_of_water__2000_2020[[#This Row],[year]])) -> 19.576048 | I35: =(R36-Estimates_of_the_use_of_water__2000_2020[[#This Row],[wat_bas_u]])/(B36-Estimates_of_the_use_of_water__2000_2020[[#This Row],[year]]) -> 19.480556 | J35: =ABS(Estimates_of_the_use_of_water__2000_2020[[#This Row],[ARC_r]]-Estimates_of_the_use_of_water__2000_2020[[#This Row],[ARC_u]]) -> 0.095491958 | K35: 1.1564259 | L35: 0.4626557 | M35: 0.68295817 | N35: 97.880238 | O35: 0.85810498 | P35: 0.31648024 | Q35: 0.94517702 | R35: 97.402778 | S35: 1.6395201 | T35: 0.69937521 | U35: 0.25832669
A36: Barbados | B36: 2015 | C36: =IF(A37=Estimates_of_the_use_of_water__2000_2020[[#This Row],[name]], B37-Estimates_of_the_use_of_water__2000_2020[[#This Row],[year]],"") -> 5 | D36: 285.327 | E36: 31.248999 | F36: 98.474445 | G36: =((F37-Estimates_of_the_use_of_water__2000_2020[[#This Row],[wat_bas_n]])/(B37-Estimates_of_the_use_of_water__2000_2020[[#This Row],[year]])) -> 0.008001136 | H36: =((N37-Estimates_of_the_use_of_water__2000_2020[[#This Row],[wat_bas_r]])/(B37-Estimates_of_the_use_of_water__2000_2020[[#This Row],[year]])) -> 0 | I36: =(R37-Estimates_of_the_use_of_water__2000_2020[[#This Row],[wat_bas_u]])/(B37-Estimates_of_the_use_of_water__2000_2020[[#This Row],[year]]) -> 0 | J36: =ABS(Estimates_of_the_use_of_water__2000_2020[[#This Row],[ARC_r]]-Estimates_of_the_use_of_water__2000_2020[[#This Row],[ARC_u]]) -> 0 | K36: 0.26749191 | L36: 1.2580634 | M36: 0
A37: Barbados | B37: 2020 | C37: =IF(A38=Estimates_of_the_use_of_water__2000_2020[[#This Row],[name]], B38-Estimates_of_the_use_of_water__2000_2020[[#This Row],[year]],"") | D37: 287.371 | E37: 31.191 | F37: 98.51445 | G37: =((F38-Estimates_of_the_use_of_water__2000_2020[[#This Row],[wat_bas_n]])/(B38-Estimates_of_the_use_of_water__2000_2020[[#This Row],[year]])) -> 0.40747667 | H37: =((N38-Estimates_of_the_use_of_water__2000_2020[[#This Row],[wat_bas_r]])/(B38-Estimates_of_the_use_of_water__2000_2020[[#This Row],[year]])) -> -19.666134 | I37: =(R38-Estimates_of_the_use_of_water__2000_2020[[#This Row],[wat_bas_u]])/(B38-Estimates_of_the_use_of_water__2000_2020[[#This Row],[year]]) -> -19.185807 | J37: =ABS(Estimates_of_the_use_of_water__2000_2020[[#This Row],[ARC_r]]-Estimates_of_the_use_of_water__2000_2020[[#This Row],[ARC_u]]) -> 0.48032728 | K37: 0.26760058 | L37: 1.217949 | M37: 0
A38: Belarus | B38: 2015 | C38: =IF(A39=Estimates_of_the_use_of_water__2000_2020[[#This Row],[name]], B39-Estimates_of_the_use_of_water__2000_2020[[#This Row],[year]],"") -> 5 | D38: 9439.4238 | E38: 77.181 | F38: 96.477067 | G38: =((F39-Estimates_of_the_use_of_water__2000_2020[[#This Row],[wat_bas_n]])/(B39-Estimates_of_the_use_of_water__2000_2020[[#This Row],[year]])) -> 0.011531798 | H38: =((N39-Estimates_of_the_use_of_water__2000_2020[[#This Row],[wat_bas_r]])/(B39-Estimates_of_the_use_of_water__2000_2020[[#This Row],[year]])) -> 0.046690142 | I38: =(R39-Estimates_of_the_use_of_water__2000_2020[[#This Row],[wat_bas_u]])/(B39-Estimates_of_the_use_of_water__2000_2020[[#This Row],[year]]) -> 0.016367688 | J38: =ABS(Estimates_of_the_use_of_water__2000_2020[[#This Row],[ARC_r]]-Estimates_of_the_use_of_water__2000_2020[[#This Row],[ARC_u]]) -> 0.030322454 | K38: 3.3001301 | L38: 0.2228028 | M38: 0 | N38: 98.330672 | O38: 0.99323911 | P38: 0.67608929 | Q38: 0 | R38: 95.929035 | S38: 3.9821754 | T38: 0.088789424 | U38: 0
A39: Belarus | B39: 2020 | C39: =IF(A40=Estimates_of_the_use_of_water__2000_2020[[#This Row],[name]], B40-Estimates_of_the_use_of_water__2000_2020[[#This Row],[year]],"") | D39: 9449.3213 | E39: 79.483002 | F39: 96.534726 | G39: =((F40-Estimates_of_the_use_of_water__2000_2020[[#This Row],[wat_bas_n]])/(B40-Estimates_of_the_use_of_water__2000_2020[[#This Row],[year]])) -> -0.69305432 | H39: =((N40-Estimates_of_the_use_of_water__2000_2020[[#This Row],[wat_bas_r]])/(B40-Estimates_of_the_use_of_water__2000_2020[[#This Row],[year]])) -> -0.28717554 | I39: =(R40-Estimates_of_the_use_of_water__2000_2020[[#This Row],[wat_bas_u]])/(B40-Estimates_of_the_use_of_water__2000_2020[[#This Row],[year]]) -> -0.79782528 | J39: =ABS(Estimates_of_the_use_of_water__2000_2020[[#This Row],[ARC_r]]-Estimates_of_the_use_of_water__2000_2020[[#This Row],[ARC_u]]) -> 0.51064974 | K39: 3.3721195 | L39: 0.093154368 | M39: 0 | N39: 98.564122 | O39: 0.9955972 | P39: 0.44028049 | Q39: 0 | R39: 96.010874 | S39: 3.9855726 | T39: 0.003553732 | U39: 0
A40: Belgium | B40: 2015 | C40: =IF(A41=Estimates_of_the_use_of_water__2000_2020[[#This Row],[name]], B41-Estimates_of_the_use_of_water__2000_2020[[#This Row],[year]],"") -> 5 | D40: 11287.931 | E40: 97.875999 | F40: 99.999998 | G40: =((F41-Estimates_of_the_use_of_water__2000_2020[[#This Row],[wat_bas_n]])/(B41-Estimates_of_the_use_of_water__2000_2020[[#This Row],[year]])) -> -2.5e-07 | H40: =((N41-Estimates_of_the_use_of_water__2000_2020[[#This Row],[wat_bas_r]])/(B41-Estimates_of_the_use_of_water__2000_2020[[#This Row],[year]])) -> 0 | I40: =(R41-Estimates_of_the_use_of_water__2000_2020[[#This Row],[wat_bas_u]])/(B41-Estimates_of_the_use_of_water__2000_2020[[#This Row],[year]]) -> 0 | J40: =ABS(Estimates_of_the_use_of_water__2000_2020[[#This Row],[ARC_r]]-Estimates_of_the_use_of_water__2000_2020[[#This Row],[ARC_u]]) -> 0 | K40: 0 | L40: 2.2980245e-06 | M40: 0 | N40: 100 | O40: 0 | P40: 0 | Q40: 0 | R40: 100 | S40: 0 | T40: 0 | U40: 0
...

Sheet Regions
A1: Column1 | B1: Column2
A2: name | B2: region
A3: Afghanistan | B3: South Asia
A4: Albania | B4: Europe & Central Asia
A5: Algeria | B5: Middle East & North Africa
A6: American Samoa | B6: East Asia & Pacific
A7: Andorra | B7: Europe & Central Asia
A8: Angola | B8: Sub-Saharan Africa
A9: Anguilla | B9: Latin America & Caribbean
A10: Antigua and Barbuda | B10: Latin America & Caribbean
A11: Argentina | B11: Latin America & Caribbean
A12: Armenia | B12: Europe & Central Asia
... A234: Zimbabwe | B234: Sub-Saharan Africa

Sheet Summary
A1: calculate the average year difference across all countries, rounded to two decimal places
A2: = | B2: =AVERAGE(Estimates_of_the_use_of_water__2000_2020[y_diff]) -> 4.7965368
A4: Calculate the minimum and maximum year difference in the same
A5: minimunm = 1
A6: maxmum = 5 | B6: =MAX(Estimates_of_the_use_of_water__2000_2020[y_diff]) -> 5
A8: How does the average year difference compare to the minimum and maximum year difference?
A9: Average Year Difference: 4.8
A10: Minimum Year Difference: 1.0
A11: Maximum Year Difference: 5.0
A13: create a histogram of the year column. Note the minimum and maximum values on the horizontal axis.
A30: Calculate the average, minimum, and maximum for each of the ARC values for access to the basic service level for each of the three population groups.
B31: Minimum | C31: Maximum | D31: Average | H31: =IFERROR((F3-[@[wat_bas_n]])/(B3-[@year]), "")
A32: ARC_n | B32: =MIN(Estimates_of_the_use_of_water__2000_2020[ARC_n]) -> -47.901587 | C32: =MAX(Estimates_of_the_use_of_water__2000_2020[ARC_n]) -> 53.813655 | D32: =AVERAGE(Estimates_of_the_use_of_water__2000_2020[ARC_n]) -> 0.19696307 | H32: =IFERROR((M3-[@[wat_bas_r]])/(B3-[@year]),"")
A33: ARC_r | B33: =MIN(Estimates_of_the_use_of_water__2000_2020[ARC_r]) -> -100 | C33: =MAX(Estimates_of_the_use_of_water__2000_2020[ARC_r]) -> 20 | D33: =AVERAGE(Estimates_of_the_use_of_water__2000_2020[ARC_r]) -> -0.67932804 | H33: =IFERROR((Q3-[@[wat_bas_u]])/(B3-[@year]),"")
A34: ARC_u | B34: =MIN(Estimates_of_the_use_of_water__2000_2020[ARC_u]) -> -99.965 | C34: =MAX(Estimates_of_the_use_of_water__2000_2020[ARC_u]) -> 48.741137 | D34: =AVERAGE(Estimates_of_the_use_of_water__2000_2020[ARC_u]) -> -0.3474114
B37: AVERAGE | C37: MINMUM | D37: MAXMUM
A38: ARC_n | B38: 0.27699608 | C38: -1.0217887 | D38: 2.7503265
A39: ARC_r | B39: 0.48445493 | C39: -1.227381 | D39: 2.6678826
A40: ARC_u | B40: 0.15446264 | C40: -1.6200868 | D40: 2.6682119
A43: calculate the number of countries that have missing ARC values, i.e., the number of “null” occurrences in each of the columns ARC_n, ARC_r, and ARC_u.
B44: Number of Missing numbers | E44: Missing2
A45: ARC_n | B45: =COUNTBLANK(cleaned!R2:R463) -> 233 | E45: =COUNTBLANK(Estimates_of_the_use_of_water__2000_2020[ARC_n]) -> 0
A46: ARC_r | B46: =COUNTBLANK(cleaned!S2:S463) -> 295 | E46: =COUNTBLANK(Estimates_of_the_use_of_water__2000_2020[ARC_r]) -> 0
A47: ARC_u | B47: =COUNTBLANK(cleaned!T3:T463) -> 280 | E47: =COUNTBLANK(Estimates_of_the_use_of_water__2000_2020[ARC_u]) -> 0
A49: calculate the number of countries that have full access across both years, i.e., the number of countries where access is 100% for both years reported.
A50: Number of countries with full access to basic water services (national): | H50: 0
A51: Number of countries with full access to basic water services (rural): | H51: 0
A52: Number of countries with full access to basic water services (urban): | H52: 0
A54: calculate the number of countries that have full access per population, i.e., the number of “full access” occurrences in each of the newly created columns ARC_n_full, ARC_r_full, and ARC_u_full.
A56: National | B56: =COUNTIF(cleaned!Y:Y, "full access") -> 152
A57: Rural | B57: =COUNTIF(cleaned!Z:Z, "full access") -> 64 | F57: COUNTA(UNIQUE(FILTER(country_range,(ARC_n_range=0)*(ARC_n_full_range<>"full access"))))
A58: Urban | B58: =COUNTIF(cleaned!AA:AA, "full access") -> 140
A60: Calculate the number of countries that have ARC values equal to zero that don’t already have full access for each of the population types: national, rural, and urban.
B61: full Access | C61: Not Full Access
B62: ARC = 0 | C62: ARC < 0 | D62: ARC > 0
A63: NATION | B63: {=COUNTA(_xlfn.UNIQUE(_xlfn._xlws.FILTER(cleaned!A:A,(cleaned!R:R=0)*(cleaned!Y:Y<>"full access"))))} -> 156 | C63: {=COUNTA(_xlfn.UNIQUE(_xlfn._xlws.FILTER(cleaned!A:A,(cleaned!R:R<0)*(cleaned!Y:Y<>"not full access"))))} -> 20 | D63: {=COUNTA(_xlfn.UNIQUE(_xlfn._xlws.FILTER(cleaned!A:A,(cleaned!R:R>0)*(cleaned!Y:Y<>"not full access"))))} -> 35
A64: RURAL | B64: {=COUNTA(_xlfn.UNIQUE(_xlfn._xlws.FILTER(cleaned!A:A,(cleaned!S:S=0)*(cleaned!Z:Z<>"full access"))))} -> 200 | C64: {=COUNTA(_xlfn.UNIQUE(_xlfn._xlws.FILTER(cleaned!A:A,(cleaned!S:S<0)*(cleaned!Z:Z<>"not full access"))))} -> 2 | D64: {=COUNTA(_xlfn.UNIQUE(_xlfn._xlws.FILTER(cleaned!A:A,(cleaned!S:S>0)*(cleaned!Z:Z<>"not full access"))))} -> 6
A65: URBAN | B65: {=COUNTA(_xlfn.UNIQUE(_xlfn._xlws.FILTER(cleaned!A:A,(cleaned!T:T=0)*(cleaned!AA:AA<>"full access"))))} -> 162 | C65: {=COUNTA(_xlfn.UNIQUE(_xlfn._xlws.FILTER(cleaned!A:A,(cleaned!T:T<0)*(cleaned!AA:AA<>"not full access"))))} -> 8 | D65: {=COUNTA(_xlfn.UNIQUE(_xlfn._xlws.FILTER(cleaned!A:A,(cleaned!T:T>0)*(cleaned!AA:AA<>"not full access"))))} -> 24
A67: check that we’ve considered all countries for the conditions—no value, full access, ARC = 0, ARC < 0, and ARC > 0, by summing the number of countries for each and comparing it to the total number of countries
A68: NATION | B68: =SUM(B63:D63) -> 211
...

Sheet cleaned
A1: name | B1: year | C1: pop_n | D1: pop_u | E1: wat_bas_n | F1: wat_lim_n | G1: wat_unimp_n | H1: wat_sur_n | I1: wat_bas_r | J1: wat_lim_r | K1: wat_unimp_r | L1: wat_sur_r | M1: wat_bas_u | N1: wat_lim_u | O1: wat_unimp_u | P1: wat_sur_u | Q1: y_diff | R1: ARC_n | S1: ARC_r | T1: ARC_u | U1: ARC_diff | V1: wat_bas_n (rounded) | W1: wat_bas_r (rounded) | X1: wat_bas_u (rounded) | Y1: ARC_n_full | Z1: ARC_r_full | AA1: ARC_u_full
A2: Afghanistan | B2: 2015 | C2: 34413.602 | D2: 24.802999 | E2: 61.339781 | F2: 3.5111995 | G2: 22.168784 | H2: 12.980236 | I2: 52.988502 | J2: 3.8611366 | K2: 26.553268 | L2: 16.597094 | M2: 86.658941 | N2: 2.4502706 | O2: 8.8760357 | P2: 2.014753 | U2: =ABS(Sheet1[[#This Row],[ARC_r]]-Sheet1[[#This Row],[ARC_u]]) -> 0 | V2: =ROUND(Sheet1[[#This Row],[wat_bas_n]],0) -> 61 | W2: =ROUND(Sheet1[[#This Row],[wat_bas_r]],0) -> 53 | X2: =ROUND(Sheet1[[#This Row],[wat_bas_u]],0) -> 87 | Y2: =IF(AND(COUNTIFS($A:$A,A2)>1, COUNTIFS($A:$A,A2,$E:$E,">99")=COUNTIFS($A:$A,A2)), "full access", "not full access") -> not full access | Z2: =IF(AND(COUNTIFS($A:$A,A2)>1, COUNTIFS($A:$A,A2,$I:$I,">99")=COUNTIFS($A:$A,A2)), "full access", "not full access") -> not full access | AA2: =IF(AND(COUNTIFS($A:$A,A2)>1, COUNTIFS($A:$A,A2,$M:$M,">99")=COUNTIFS($A:$A,A2)), "full access", "not full access") -> not full access
A3: Afghanistan | B3: 2020 | C3: 38928.34 | D3: 26.025999 | E3: 75.091413 | F3: 1.4475417 | G3: 14.560263 | H3: 8.9007822 | I3: 66.327915 | J3: 1.9568249 | K3: 19.682949 | L3: 12.032311 | M3: 100 | N3: 0 | O3: 0 | P3: 0 | Q3: 5 | R3: 2.7503265 | S3: 2.6678826 | T3: 2.6682119 | U3: =ABS(Sheet1[[#This Row],[ARC_r]]-Sheet1[[#This Row],[ARC_u]]) -> 0.000329218 | V3: =ROUND(Sheet1[[#This Row],[wat_bas_n]],0) -> 75 | W3: =ROUND(Sheet1[[#This Row],[wat_bas_r]],0) -> 66 | X3: =ROUND(Sheet1[[#This Row],[wat_bas_u]],0) -> 100 | Y3: =IF(AND(COUNTIFS($A:$A,A3)>1, COUNTIFS($A:$A,A3,$E:$E,">99")=COUNTIFS($A:$A,A3)), "full access", "not full access") -> not full access | Z3: =IF(AND(COUNTIFS($A:$A,A3)>1, COUNTIFS($A:$A,A3,$I:$I,">99")=COUNTIFS($A:$A,A3)), "full access", "not full access") -> not full access | AA3: =IF(AND(COUNTIFS($A:$A,A3)>1, COUNTIFS($A:$A,A3,$M:$M,">99")=COUNTIFS($A:$A,A3)), "full access", "not full access") -> not full access
A4: Albania | B4: 2015 | C4: 2890.5239 | D4: 57.433998 | E4: 93.394325 | F4: 3.6263837 | G4: 2.979291 | H4: 0 | I4: 90.627275 | J4: 5.2631726 | K4: 4.1095527 | L4: 0 | M4: 95.445067 | N4: 2.4133118 | O4: 2.1416212 | P4: 0 | U4: =ABS(Sheet1[[#This Row],[ARC_r]]-Sheet1[[#This Row],[ARC_u]]) -> 0 | V4: =ROUND(Sheet1[[#This Row],[wat_bas_n]],0) -> 93 | W4: =ROUND(Sheet1[[#This Row],[wat_bas_r]],0) -> 91 | X4: =ROUND(Sheet1[[#This Row],[wat_bas_u]],0) -> 95 | Y4: =IF(AND(COUNTIFS($A:$A,A4)>1, COUNTIFS($A:$A,A4,$E:$E,">99")=COUNTIFS($A:$A,A4)), "full access", "not full access") -> not full access | Z4: =IF(AND(COUNTIFS($A:$A,A4)>1, COUNTIFS($A:$A,A4,$I:$I,">99")=COUNTIFS($A:$A,A4)), "full access", "not full access") -> not full access | AA4: =IF(AND(COUNTIFS($A:$A,A4)>1, COUNTIFS($A:$A,A4,$M:$M,">99")=COUNTIFS($A:$A,A4)), "full access", "not full access") -> not full access
A5: Albania | B5: 2020 | C5: 2877.8 | D5: 62.112 | E5: 95.068039 | F5: 1.8846561 | G5: 3.0473051 | H5: 0 | I5: 94.091358 | J5: 2.305265 | K5: 3.603377 | L5: 0 | M5: 95.663809 | N5: 1.6280868 | O5: 2.7081041 | P5: 0 | Q5: 5 | R5: 0.3347427 | S5: 0.69281669 | T5: 0.043748432 | U5: =ABS(Sheet1[[#This Row],[ARC_r]]-Sheet1[[#This Row],[ARC_u]]) -> 0.64906826 | V5: =ROUND(Sheet1[[#This Row],[wat_bas_n]],0) -> 95 | W5: =ROUND(Sheet1[[#This Row],[wat_bas_r]],0) -> 94 | X5: =ROUND(Sheet1[[#This Row],[wat_bas_u]],0) -> 96 | Y5: =IF(AND(COUNTIFS($A:$A,A5)>1, COUNTIFS($A:$A,A5,$E:$E,">99")=COUNTIFS($A:$A,A5)), "full access", "not full access") -> not full access | Z5: =IF(AND(COUNTIFS($A:$A,A5)>1, COUNTIFS($A:$A,A5,$I:$I,">99")=COUNTIFS($A:$A,A5)), "full access", "not full access") -> not full access | AA5: =IF(AND(COUNTIFS($A:$A,A5)>1, COUNTIFS($A:$A,A5,$M:$M,">99")=COUNTIFS($A:$A,A5)), "full access", "not full access") -> not full access
A6: Algeria | B6: 2015 | C6: 39728.02 | D6: 70.848 | E6: 93.409562 | F6: 5.1577809 | G6: 1.2754647 | H6: 0.15719289 | I6: 88.352707 | J6: 8.6857531 | K6: 2.5804318 | L6: 0.38110822 | M6: 95.490315 | N6: 3.7061173 | O6: 0.73851009 | P6: 0.065057898 | U6: =ABS(Sheet1[[#This Row],[ARC_r]]-Sheet1[[#This Row],[ARC_u]]) -> 0 | V6: =ROUND(Sheet1[[#This Row],[wat_bas_n]],0) -> 93 | W6: =ROUND(Sheet1[[#This Row],[wat_bas_r]],0) -> 88 | X6: =ROUND(Sheet1[[#This Row],[wat_bas_u]],0) -> 95 | Y6: =IF(AND(COUNTIFS($A:$A,A6)>1, COUNTIFS($A:$A,A6,$E:$E,">99")=COUNTIFS($A:$A,A6)), "full access", "not full access") -> not full access | Z6: =IF(AND(COUNTIFS($A:$A,A6)>1, COUNTIFS($A:$A,A6,$I:$I,">99")=COUNTIFS($A:$A,A6)), "full access", "not full access") -> not full access | AA6: =IF(AND(COUNTIFS($A:$A,A6)>1, COUNTIFS($A:$A,A6,$M:$M,">99")=COUNTIFS($A:$A,A6)), "full access", "not full access") -> not full access
A7: Algeria | B7: 2020 | C7: 43851.043 | D7: 73.733002 | E7: 94.43733 | F7: 4.9858808 | G7: 0.53183666 | H7: 0.044952533 | I7: 90.037538 | J7: 8.7967221 | K7: 0.99460303 | L7: 0.17113693 | M7: 96.004736 | N7: 3.6282886 | O7: 0.36697555 | P7: 0 | Q7: 5 | R7: 0.20555369 | S7: 0.33696621 | T7: 0.10288423 | U7: =ABS(Sheet1[[#This Row],[ARC_r]]-Sheet1[[#This Row],[ARC_u]]) -> 0.23408198 | V7: =ROUND(Sheet1[[#This Row],[wat_bas_n]],0) -> 94 | W7: =ROUND(Sheet1[[#This Row],[wat_bas_r]],0) -> 90 | X7: =ROUND(Sheet1[[#This Row],[wat_bas_u]],0) -> 96 | Y7: =IF(AND(COUNTIFS($A:$A,A7)>1, COUNTIFS($A:$A,A7,$E:$E,">99")=COUNTIFS($A:$A,A7)), "full access", "not full access") -> not full access | Z7: =IF(AND(COUNTIFS($A:$A,A7)>1, COUNTIFS($A:$A,A7,$I:$I,">99")=COUNTIFS($A:$A,A7)), "full access", "not full access") -> not full access | AA7: =IF(AND(COUNTIFS($A:$A,A7)>1, COUNTIFS($A:$A,A7,$M:$M,">99")=COUNTIFS($A:$A,A7)), "full access", "not full access") -> not full access
A8: American Samoa | B8: 2015 | C8: 55.806 | D8: 87.238007 | E8: 99.619103 | F8: 0 | G8: 0.38089685 | H8: 0 | U8: =ABS(Sheet1[[#This Row],[ARC_r]]-Sheet1[[#This Row],[ARC_u]]) -> 0 | V8: =ROUND(Sheet1[[#This Row],[wat_bas_n]],0) -> 100 | W8: =ROUND(Sheet1[[#This Row],[wat_bas_r]],0) -> 0 | X8: =ROUND(Sheet1[[#This Row],[wat_bas_u]],0) -> 0 | Y8: =IF(AND(COUNTIFS($A:$A,A8)>1, COUNTIFS($A:$A,A8,$E:$E,">99")=COUNTIFS($A:$A,A8)), "full access", "not full access") -> full access | Z8: =IF(AND(COUNTIFS($A:$A,A8)>1, COUNTIFS($A:$A,A8,$I:$I,">99")=COUNTIFS($A:$A,A8)), "full access", "not full access") -> not full access | AA8: =IF(AND(COUNTIFS($A:$A,A8)>1, COUNTIFS($A:$A,A8,$M:$M,">99")=COUNTIFS($A:$A,A8)), "full access", "not full access") -> not full access
A9: American Samoa | B9: 2020 | C9: 55.196999 | D9: 87.153 | E9: 99.773772 | F9: 0 | G9: 0.22622834 | H9: 0 | Q9: 5 | R9: 0.030933702 | U9: =ABS(Sheet1[[#This Row],[ARC_r]]-Sheet1[[#This Row],[ARC_u]]) -> 0 | V9: =ROUND(Sheet1[[#This Row],[wat_bas_n]],0) -> 100 | W9: =ROUND(Sheet1[[#This Row],[wat_bas_r]],0) -> 0 | X9: =ROUND(Sheet1[[#This Row],[wat_bas_u]],0) -> 0 | Y9: =IF(AND(COUNTIFS($A:$A,A9)>1, COUNTIFS($A:$A,A9,$E:$E,">99")=COUNTIFS($A:$A,A9)), "full access", "not full access") -> full access | Z9: =IF(AND(COUNTIFS($A:$A,A9)>1, COUNTIFS($A:$A,A9,$I:$I,">99")=COUNTIFS($A:$A,A9)), "full access", "not full access") -> not full access | AA9: =IF(AND(COUNTIFS($A:$A,A9)>1, COUNTIFS($A:$A,A9,$M:$M,">99")=COUNTIFS($A:$A,A9)), "full access", "not full access") -> not full access
A10: Andorra | B10: 2015 | C10: 77.992996 | D10: 88.344994 | E10: 99.999998 | F10: 0 | G10: 2.4455384e-06 | H10: 0 | I10: 100 | J10: 0 | K10: 0 | L10: 0 | M10: 100 | N10: 0 | O10: 0 | P10: 0 | U10: =ABS(Sheet1[[#This Row],[ARC_r]]-Sheet1[[#This Row],[ARC_u]]) -> 0 | V10: =ROUND(Sheet1[[#This Row],[wat_bas_n]],0) -> 100 | W10: =ROUND(Sheet1[[#This Row],[wat_bas_r]],0) -> 100 | X10: =ROUND(Sheet1[[#This Row],[wat_bas_u]],0) -> 100 | Y10: =IF(AND(COUNTIFS($A:$A,A10)>1, COUNTIFS($A:$A,A10,$E:$E,">99")=COUNTIFS($A:$A,A10)), "full access", "not full access") -> full access | Z10: =IF(AND(COUNTIFS($A:$A,A10)>1, COUNTIFS($A:$A,A10,$I:$I,">99")=COUNTIFS($A:$A,A10)), "full access", "not full access") -> full access | AA10: =IF(AND(COUNTIFS($A:$A,A10)>1, COUNTIFS($A:$A,A10,$M:$M,">99")=COUNTIFS($A:$A,A10)), "full access", "not full access") -> full access
A11: Andorra | B11: 2020 | C11: 77.264999 | D11: 87.916 | E11: 100 | F11: 0 | G11: 0 | H11: 0 | I11: 100 | J11: 0 | K11: 0 | L11: 0 | M11: 100 | N11: 0 | O11: 0 | P11: 0 | Q11: 5 | R11: 1.23e-06 | S11: 0 | T11: 0 | U11: =ABS(Sheet1[[#This Row],[ARC_r]]-Sheet1[[#This Row],[ARC_u]]) -> 0 | V11: =ROUND(Sheet1[[#This Row],[wat_bas_n]],0) -> 100 | W11: =ROUND(Sheet1[[#This Row],[wat_bas_r]],0) -> 100 | X11: =ROUND(Sheet1[[#This Row],[wat_bas_u]],0) -> 100 | Y11: =IF(AND(COUNTIFS($A:$A,A11)>1, COUNTIFS($A:$A,A11,$E:$E,">99")=COUNTIFS($A:$A,A11)), "full access", "not full access") -> full access | Z11: =IF(AND(COUNTIFS($A:$A,A11)>1, COUNTIFS($A:$A,A11,$I:$I,">99")=COUNTIFS($A:$A,A11)), "full access", "not full access") -> full access | AA11: =IF(AND(COUNTIFS($A:$A,A11)>1, COUNTIFS($A:$A,A11,$M:$M,">99")=COUNTIFS($A:$A,A11)), "full access", "not full access") -> full access
A12: Angola | B12: 2015 | C12: 27884.381 | D12: 63.445995 | E12: 54.316928 | F12: 11.368619 | G12: 17.372356 | H12: 16.942097 | I12: 26.714369 | J12: 9.9310693 | K12: 21.725308 | L12: 41.629254 | M12: 70.219965 | N12: 12.196853 | O12: 14.864431 | P12: 2.7187499 | U12: =ABS(Sheet1[[#This Row],[ARC_r]]-Sheet1[[#This Row],[ARC_u]]) -> 0 | V12: =ROUND(Sheet1[[#This Row],[wat_bas_n]],0) -> 54 | W12: =ROUND(Sheet1[[#This Row],[wat_bas_r]],0) -> 27 | X12: =ROUND(Sheet1[[#This Row],[wat_bas_u]],0) -> 70 | Y12: =IF(AND(COUNTIFS($A:$A,A12)>1, COUNTIFS($A:$A,A12,$E:$E,">99")=COUNTIFS($A:$A,A12)), "full access", "not full access") -> not full access | Z12: =IF(AND(COUNTIFS($A:$A,A12)>1, COUNTIFS($A:$A,A12,$I:$I,">99")=COUNTIFS($A:$A,A12)), "full access", "not full access") -> not full access | AA12: =IF(AND(COUNTIFS($A:$A,A12)>1, COUNTIFS($A:$A,A12,$M:$M,">99")=COUNTIFS($A:$A,A12)), "full access", "not full access") -> not full access
A13: Angola | B13: 2020 | C13: 32866.27 | D13: 66.824997 | E13: 57.167738 | F13: 9.2873499 | G13: 19.450825 | H13: 14.094087 | I13: 27.808227 | J13: 8.7404884 | K13: 22.933153 | L13: 40.518132 | M13: 71.743149 | N13: 9.5588375 | O13: 17.722035 | P13: 0.97597916 | Q13: 5 | R13: 0.57016185 | S13: 0.21877144 | T13: 0.3046367 | U13: =ABS(Sheet1[[#This Row],[ARC_r]]-Sheet1[[#This Row],[ARC_u]]) -> 0.085865258 | V13: =ROUND(Sheet1[[#This Row],[wat_bas_n]],0) -> 57 | W13: =ROUND(Sheet1[[#This Row],[wat_bas_r]],0) -> 28 | X13: =ROUND(Sheet1[[#This Row],[wat_bas_u]],0) -> 72 | Y13: =IF(AND(COUNTIFS($A:$A,A13)>1, COUNTIFS($A:$A,A13,$E:$E,">99")=COUNTIFS($A:$A,A13)), "full access", "not full access") -> not full access | Z13: =IF(AND(COUNTIFS($A:$A,A13)>1, COUNTIFS($A:$A,A13,$I:$I,">99")=COUNTIFS($A:$A,A13)), "full access", "not full access") -> not full access | AA13: =IF(AND(COUNTIFS($A:$A,A13)>1, COUNTIFS($A:$A,A13,$M:$M,">99")=COUNTIFS($A:$A,A13)), "full access", "not full access") -> not full access
A14: Anguilla | B14: 2015 | C14: 14.279 | D14: 100 | E14: 97.482274 | F14: 0 | G14: 2.5177258 | H14: 0 | M14: 97.482274 | N14: 0 | O14: 2.5177258 | P14: 0 | U14: =ABS(Sheet1[[#This Row],[ARC_r]]-Sheet1[[#This Row],[ARC_u]]) -> 0 | V14: =ROUND(Sheet1[[#This Row],[wat_bas_n]],0) -> 97 | W14: =ROUND(Sheet1[[#This Row],[wat_bas_r]],0) -> 0 | X14: =ROUND(Sheet1[[#This Row],[wat_bas_u]],0) -> 97 | Y14: =IF(AND(COUNTIFS($A:$A,A14)>1, COUNTIFS($A:$A,A14,$E:$E,">99")=COUNTIFS($A:$A,A14)), "full access", "not full access") -> not full access | Z14: =IF(AND(COUNTIFS($A:$A,A14)>1, COUNTIFS($A:$A,A14,$I:$I,">99")=COUNTIFS($A:$A,A14)), "full access", "not full access") -> not full access | AA14: =IF(AND(COUNTIFS($A:$A,A14)>1, COUNTIFS($A:$A,A14,$M:$M,">99")=COUNTIFS($A:$A,A14)), "full access", "not full access") -> not full access
A15: Anguilla | B15: 2017 | C15: 14.588 | D15: 100 | E15: 97.482274 | F15: 0 | G15: 2.5177258 | H15: 0 | M15: 97.482274 | N15: 0 | O15: 2.5177258 | P15: 0 | Q15: 2 | R15: 0 | T15: 0 | U15: =ABS(Sheet1[[#This Row],[ARC_r]]-Sheet1[[#This Row],[ARC_u]]) -> 0 | V15: =ROUND(Sheet1[[#This Row],[wat_bas_n]],0) -> 97 | W15: =ROUND(Sheet1[[#This Row],[wat_bas_r]],0) -> 0 | X15: =ROUND(Sheet1[[#This Row],[wat_bas_u]],0) -> 97 | Y15: =IF(AND(COUNTIFS($A:$A,A15)>1, COUNTIFS($A:$A,A15,$E:$E,">99")=COUNTIFS($A:$A,A15)), "full access", "not full access") -> not full access | Z15: =IF(AND(COUNTIFS($A:$A,A15)>1, COUNTIFS($A:$A,A15,$I:$I,">99")=COUNTIFS($A:$A,A15)), "full access", "not full access") -> not full access | AA15: =IF(AND(COUNTIFS($A:$A,A15)>1, COUNTIFS($A:$A,A15,$M:$M,">99")=COUNTIFS($A:$A,A15)), "full access", "not full access") -> not full access
A16: Antigua and Barbuda | B16: 2015 | C16: 93.570999 | D16: 25 | E16: 96.739186 | F16: 0 | G16: 3.1663476 | H16: 0.094466114 | U16: =ABS(Sheet1[[#This Row],[ARC_r]]-Sheet1[[#This Row],[ARC_u]]) -> 0 | V16: =ROUND(Sheet1[[#This Row],[wat_bas_n]],0) -> 97 | W16: =ROUND(Sheet1[[#This Row],[wat_bas_r]],0) -> 0 | X16: =ROUND(Sheet1[[#This Row],[wat_bas_u]],0) -> 0 | Y16: =IF(AND(COUNTIFS($A:$A,A16)>1, COUNTIFS($A:$A,A16,$E:$E,">99")=COUNTIFS($A:$A,A16)), "full access", "not full access") -> not full access | Z16: =IF(AND(COUNTIFS($A:$A,A16)>1, COUNTIFS($A:$A,A16,$I:$I,">99")=COUNTIFS($A:$A,A16)), "full access", "not full access") -> not full access | AA16: =IF(AND(COUNTIFS($A:$A,A16)>1, COUNTIFS($A:$A,A16,$M:$M,">99")=COUNTIFS($A:$A,A16)), "full access", "not full access") -> not full access
A17: Antigua and Barbuda | B17: 2017 | C17: 95.425003 | D17: 24.713001 | E17: 96.739186 | F17: 0 | G17: 3.1663476 | H17: 0.094466114 | Q17: 2 | R17: 0 | U17: =ABS(Sheet1[[#This Row],[ARC_r]]-Sheet1[[#This Row],[ARC_u]]) -> 0 | V17: =ROUND(Sheet1[[#This Row],[wat_bas_n]],0) -> 97 | W17: =ROUND(Sheet1[[#This Row],[wat_bas_r]],0) -> 0 | X17: =ROUND(Sheet1[[#This Row],[wat_bas_u]],0) -> 0 | Y17: =IF(AND(COUNTIFS($A:$A,A17)>1, COUNTIFS($A:$A,A17,$E:$E,">99")=COUNTIFS($A:$A,A17)), "full access", "not full access") -> not full access | Z17: =IF(AND(COUNTIFS($A:$A,A17)>1, COUNTIFS($A:$A,A17,$I:$I,">99")=COUNTIFS($A:$A,A17)), "full access", "not full access") -> not full access | AA17: =IF(AND(COUNTIFS($A:$A,A17)>1, COUNTIFS($A:$A,A17,$M:$M,">99")=COUNTIFS($A:$A,A17)), "full access", "not full access") -> not full access
A18: Argentina | B18: 2015 | C18: 43075.414 | D18: 91.502998 | E18: 98.966588 | F18: 0 | G18: 0.66491438 | H18: 0.36849747 | I18: 92.98366 | J18: 0 | K18: 2.6795449 | L18: 4.3367951 | M18: 99.522163 | N18: 0 | O18: 0.47783695 | P18: 0 | U18: =ABS(Sheet1[[#This Row],[ARC_r]]-Sheet1[[#This Row],[ARC_u]]) -> 0 | V18: =ROUND(Sheet1[[#This Row],[wat_bas_n]],0) -> 99 | W18: =ROUND(Sheet1[[#This Row],[wat_bas_r]],0) -> 93 | X18: =ROUND(Sheet1[[#This Row],[wat_bas_u]],0) -> 100 | Y18: =IF(AND(COUNTIFS($A:$A,A18)>1, COUNTIFS($A:$A,A18,$E:$E,">99")=COUNTIFS($A:$A,A18)), "full access", "not full access") -> not full access | Z18: =IF(AND(COUNTIFS($A:$A,A18)>1, COUNTIFS($A:$A,A18,$I:$I,">99")=COUNTIFS($A:$A,A18)), "full access", "not full access") -> not full access | AA18: =IF(AND(COUNTIFS($A:$A,A18)>1, COUNTIFS($A:$A,A18,$M:$M,">99")=COUNTIFS($A:$A,A18)), "full access", "not full access") -> full access
A19: Argentina | B19: 2020 | C19: 45195.777 | D19: 92.111 | M19: 99.790421 | N19: 0 | O19: 0.20957935 | P19: 0 | Q19: 5 | T19: 0.05365152 | U19: =ABS(Sheet1[[#This Row],[ARC_r]]-Sheet1[[#This Row],[ARC_u]]) -> 0.05365152 | V19: =ROUND(Sheet1[[#This Row],[wat_bas_n]],0) -> 0 | W19: =ROUND(Sheet1[[#This Row],[wat_bas_r]],0) -> 0 | X19: =ROUND(Sheet1[[#This Row],[wat_bas_u]],0) -> 100 | Y19: =IF(AND(COUNTIFS($A:$A,A19)>1, COUNTIFS($A:$A,A19,$E:$E,">99")=COUNTIFS($A:$A,A19)), "full access", "not full access") -> not full access | Z19: =IF(AND(COUNTIFS($A:$A,A19)>1, COUNTIFS($A:$A,A19,$I:$I,">99")=COUNTIFS($A:$A,A19)), "full access", "not full access") -> not full access | AA19: =IF(AND(COUNTIFS($A:$A,A19)>1, COUNTIFS($A:$A,A19,$M:$M,">99")=COUNTIFS($A:$A,A19)), "full access", "not full access") -> full access
